---
title: Workarounds
authors: apevec, arifali, avladu, dustymabe, eglynn, ekuris, eyepv6, fbayhan, flaper87,
  hma, iovadia, jpichon, jruzicka, kashyap, larsks, mmagr, pixelbeat, rbowen, rdo,
  rohara, rwmjones, sasha, shardy, sschinna, stoner, stzilli, tshefi, vaneldik, weshayutin,
  whayutin, xqueralt
wiki_title: Workarounds
wiki_revision_count: 100
wiki_last_updated: 2015-05-07
---

# Workarounds

See [Workaround_archive](Workaround_archive) for workarounds that we believe to be resolved. Please move them back here if they appear to still be necessary.

## Unable to start nova-api

*   **Bug:** <https://bugzilla.redhat.com/show_bug.cgi?id=1139771>
*   **Affects:** Fedora 20, CentOS7

#### symptoms

Packstack fails with the error:

    Error: Could not start Service[nova-api]: Execution of '/sbin/service openstack-nova-api start' returned 1: 

/var/log/audit/audit.log contains:

    type=AVC msg=audit(1412109980.125:4612): avc:  denied  { getattr } for  pid=3296 comm="nova-api" name="/" dev="tmpfs" ino=13317 scontext=system_u:system_r:nova_api_t:s0 tcontext=system_u:object_r:tmpfs_t:s0 tclass=filesystem permissive=0

#### workaround

You can place selinux in permissive mode:

    # setenforce 0

You can build an selinux module that permits the necessary access. On a Fedora 20 machine, place this in a file called nova_allow_tmpfs.te:

    module nova_allow_tmpfs 1.0;

    require {
        type tmpfs_t;
        type nova_api_t;
        class filesystem getattr;
    }

    #============= nova_api_t ==============
    allow nova_api_t tmpfs_t:filesystem getattr;

On a RHEL7 or CentOS7 server, place this in a file called nova_allow_tmpfs.te:

    module nova_allow_tmpfs 1.0;

    require {
        type tmpfs_t;
        type nova_api_t;
        class filesystem getattr;
        class dir { search write add_name remove_name } ;
        class file { create read write open link unlink getattr } ;
    }

    #============= nova_api_t ==============
    allow nova_api_t tmpfs_t:filesystem getattr;
    allow nova_api_t tmpfs_t:dir { search write add_name remove_name } ;
    allow nova_api_t tmpfs_t:file { create read write open link unlink getattr } ;

And then:

    # yum -y install selinux-policy-devel
    # make -f /usr/share/selinux/devel/Makefile nova_allow_tmpfs.pp
    Compiling targeted nova_allow_tmpfs module
    /usr/bin/checkmodule:  loading policy configuration from tmp/nova_allow_tmpfs.tmp
    /usr/bin/checkmodule:  policy configuration loaded
    /usr/bin/checkmodule:  writing binary representation (version 17) to tmp/nova_allow_tmpfs.mod
    Creating targeted nova_allow_tmpfs.pp policy package
    rm tmp/nova_allow_tmpfs.mod.fc tmp/nova_allow_tmpfs.mod
    # semodule -i nova_allow_tmpfs.pp

## Provisioning of glance does not work for demo environment

*   **Bug:** <https://bugzilla.redhat.com/show_bug.cgi?id=1148346>
*   **Affects:** CentOS 7, RHEL 7, Fedora 21

#### symptoms

Packstack fails with the following error

    10.0.0.1_provision_glance.pp:                     [ ERROR ]             
    Applying Puppet manifests                         [ ERROR ]

    ERROR : Error appeared during Puppet run: 10.0.0.1_provision_glance.pp
    Error: Could not prefetch glance_image provider 'glance': Execution of '/usr/bin/glance -T services -I glance -K 86f175e8c0884d77 -N http://10.0.0.1:35357/v2.0/ index' returned 2: usage: glance [--version] [-d] [-v] [--get-schema] [--timeout TIMEOUT]
    You will find full trace in log /var/tmp/packstack/20141001-091112-m6iWqu/manifests/10.0.0.1_provision_glance.pp.log
    Please check log file /var/tmp/packstack/20141001-091112-m6iWqu/openstack-setup.log for more information

#### workaround

You can downgrade to the earlier version of `python-glanceclient`:

    yum downgrade python-glanceclient

Or you can configure packstack to not provision a demo user, images, etc by setting `CONFIG_PROVISION_DEMO=n` in the packstack answers file.

After making one of the above changes, re-run packstack with:

     packstack --answer-file=<generated packstack file>

## Enabling Tempest gives Glance error

*   **Bug:** <https://bugzilla.redhat.com/show_bug.cgi?id=1148459>
*   **Affects:** CentOS7

#### symptoms

         ERROR : Error appeared during Puppet run: 10.0.0.1_provision_glance.pp
         Error: Could not prefetch glance_image provider 'glance': Execution of '/usr/bin/glance -T 
            services -I glance -K 0f75673432f84bef -N `[`http://10.0.0.1:35357/v2.0/`](http://10.0.0.1:35357/v2.0/)` index' returned 
            2: usage: glance [--version] [-d] [-v] [--get-schema] [--timeout TIMEOUT]
         You will find full trace in log /var/tmp/packstack/20141001-131918-KS5XQ4/manifests/10.0.0.1_provision_glance.pp.log

#### workaround

          yum downgrade python-glanceclient

## Packstack --allinone fails to remove firewalld

*   **Bug:** <https://bugzilla.redhat.com/show_bug.cgi?id=1148426>
*   **Affects:** Fedora 20, Fedora 21, CentOS7

#### symptoms

        Applying 192.168.122.48_prescript.pp
        192.168.122.48_prescript.pp:                      [ ERROR ]            
        Applying Puppet manifests                         [ ERROR ]

        ERROR : Error appeared during Puppet run: 192.168.122.48_prescript.pp
        Error: Execution of '/usr/bin/rpm -e firewalld-0.3.11-3.fc20.noarch' returned 1: error: Failed dependencies:
        You will find full trace in log /var/tmp/packstack/20141001-080818-TOTPkh/manifests/192.168.122.48_prescript.pp.log

The log contains:

          Error: Execution of '/usr/bin/rpm -e firewalld-0.3.9-7.el7.noarch' returned 1: error: Failed dependencies:
              firewalld >= 0.3.5-1 is needed by (installed) anaconda-19.31.79-1.el7.centos.4.x86_64
              firewalld = 0.3.9-7.el7 is needed by (installed) firewall-config-0.3.9-7.el7.noarch

#### workaround

         yum remove firewalld

This will also remove the anaconda package dependency

Then re-run packstack with the same answer file.

## Packstack fails when mariadb-server is installed

*   **Bug:** <https://bugzilla.redhat.com/show_bug.cgi?id=1148578>
*   **Affects:** Fedora 20

#### symptoms

    192.168.122.48_mysql.pp:                          [ ERROR ]        
    Applying Puppet manifests                         [ ERROR ]

    ERROR : Error appeared during Puppet run: 192.168.122.48_mysql.pp
    Error: Execution of '/usr/bin/yum -d 0 -e 0 -y install mariadb-galera-server' returned 1: Error: mariadb-galera-server conflicts with 1:mariadb-server-5.5.39-1.fc20.x86_64
    You will find full trace in log /var/tmp/packstack/20141001-084831-5JyrbC/manifests/192.168.122.48_mysql.pp.log
    Please check log file /var/tmp/packstack/20141001-084831-5JyrbC/openstack-setup.log for more information

#### workaround

Remove the mariadb-server package: yum remove mariadb-server

And rerun packstack

## packstack --allinone fails on Centos7 with: ERROR : Cinder's volume group 'cinder-volumes' could not be created.

*   Bug: <https://bugzilla.redhat.com/show_bug.cgi?id=1148552>

#### symptoms

packstack --allinone fails on Centos7 with: ERROR : Cinder's volume group 'cinder-volumes' could not be created.

#### workaround

    dd if=/dev/zero of=cinder-volumes bs=1 count=0 seek=2G && losetup /dev/loop2 cinder-volumes && pvcreate /dev/loop2 && vgcreate cinder-volumes /dev/loop2

## rabbitmq-server does not start

*   **Bug:** <https://bugzilla.redhat.com/show_bug.cgi?id=1148604>
*   **Affects:** Fedora 21

#### symptoms

Packstack fails with the following error

    Applying 192.168.1.127_mysql.pp
    192.168.1.127_amqp.pp:                            [ ERROR ]       
    Applying Puppet manifests                         [ ERROR ]

    ERROR : Error appeared during Puppet run: 192.168.1.127_amqp.pp
    Error: Could not start Service[rabbitmq-server]: Execution of '/sbin/service rabbitmq-server start' returned 1: Redirecting to /bin/systemctl start  rabbitmq-server.service
    You will find full trace in log /var/tmp/packstack/20141002-113627-IM6EYW/manifests/192.168.1.127_amqp.pp.log
    Please check log file /var/tmp/packstack/20141002-113627-IM6EYW/openstack-setup.log for more information

#### workaround

You can upgrade to a version of erlang-sd_notify >= 0.1-4. No version is currently in the repo so you have to directly download from koji. The command below should check the repo first (preferred) and then fallback to koji if necessary.

    yum install -y erlang-sd_notify-0.1-4 || yum install -y http://kojipkgs.fedoraproject.org/packages/erlang-sd_notify/0.1/4.fc21/data/signed/95a43f54/x86_64/erlang-sd_notify-0.1-4.fc21.x86_64.rpm

After making the above change, re-run packstack with:

     packstack --answer-file=<generated packstack file>

## mariadb fails to start

*   **Bug:** <https://bugzilla.redhat.com/show_bug.cgi?id=1141458>
*   **Affects:** Fedora 21

#### symptoms

Packstack fails with the following error

    192.168.1.127_mysql.pp:                           [ ERROR ]       
    Applying Puppet manifests                         [ ERROR ]

    ERROR : Error appeared during Puppet run: 192.168.1.127_mysql.pp
    Error: Could not start Service[mysqld]: Execution of '/sbin/service mariadb start' returned 1: Redirecting to /bin/systemctl start  mariadb.service
    You will find full trace in log /var/tmp/packstack/20141002-123813-7E6EEK/manifests/192.168.1.127_mysql.pp.log
    Please check log file /var/tmp/packstack/20141002-123813-7E6EEK/openstack-setup.log for more information

#### workaround

For now comment out the "plugin-load-add=ha_connect.so" line in /etc/my.cnf.d/connect.cnf.

    sed -i s/plugin-load-add=ha_connect.so/#plugin-load-add=ha_connect.so/ /etc/my.cnf.d/connect.cnf

After making the above change, re-run packstack with:

     packstack --answer-file=<generated packstack file>

## nova boot: failure creating veth devices

*   **Bug:** <https://bugzilla.redhat.com/show_bug.cgi?id=1149043>
*   **Affects:** Fedora 21

#### symptoms

Booting an instance fails and says 'No valid host was found.' In nova-compute.log:

     [instance: d9ad23e8-ebf6-4d21-9004-991f893fd500] ProcessExecutionError: Unexpected error while running command.
     [instance: d9ad23e8-ebf6-4d21-9004-991f893fd500] Command: sudo nova-rootwrap /etc/nova/rootwrap.conf ip link add qvb55064258-0a type veth peer name qvo55064258-0a
     [instance: d9ad23e8-ebf6-4d21-9004-991f893fd500] Exit code: 255
     [instance: d9ad23e8-ebf6-4d21-9004-991f893fd500] Stdout: ''
     [instance: d9ad23e8-ebf6-4d21-9004-991f893fd500] Stderr: 'Error: argument "qvb55064258-0a" is wrong: Unknown device\n'

#### workaround

Patch the /usr/lib/python2.7/site-packages/nova/network/linux_net.py file to give arguments that /usr/sbin/ip will accept:

    patch -b -d/ -p0  << EOF
    --- /usr/lib/python2.7/site-packages/nova/network/linux_net.py.orig     2014-10-02 17:00:19.620007092 -0400
    +++ /usr/lib/python2.7/site-packages/nova/network/linux_net.py  2014-10-02 16:40:31.514361599 -0400
    @@ -1316,7 +1316,7 @@
         for dev in [dev1_name, dev2_name]:
             delete_net_dev(dev)

    -    utils.execute('ip', 'link', 'add', dev1_name, 'type', 'veth', 'peer',
    +    utils.execute('ip', 'link', 'add', 'name', dev1_name, 'type', 'veth', 'peer',
                       'name', dev2_name, run_as_root=True)
         for dev in [dev1_name, dev2_name]:
             utils.execute('ip', 'link', 'set', dev, 'up', run_as_root=True)
    EOF

After making the above change, restart openstack services:

     openstack-service restart

## Example Problem Description

*   **Bug:** <https://bugzilla.redhat.com/show_bug.cgi?id=12345>
*   **Affects:** Operating Systems Affected

#### symptoms

Describe symptoms here

#### workaround

Describe how to work around the problem.
